Workbook

Sheet districts_app
A1: district_id | B1: il | C1: ilce | D1: full_name | E1: default_overall_score_100 | F1: model_rank | G1: sege_rank | H1: sege_score | I1: sege_tier | J1: population_2024 | K1: social_culture_score_20 | L1: sea_access_score_20 | M1: sea_category | N1: earthquake_safety_score_20 | O1: earthquake_risk_band | P1: low_crowding_score_20 | Q1: judicial_low_event_score_20 | R1: judicial_region | S1: affordability_score_20 | T1: endeksa_data_level | U1: sale_price_m2_try | V1: rent_price_m2_try | W1: avg_rent_try | X1: avg_home_price_try | Y1: rent_increase_1y_pct | Z1: amortization_years | AA1: listing_stock_note | AB1: data_note
A2: trabzon-ortahisar | B2: Trabzon | C2: Ortahisar | D2: Trabzon / Ortahisar | E2: 74.9 | F2: 1 | G2: 56 | H2: 1.81 | I2: 1 | J2: 330836 | K2: 2.96 | L2: 20 | M2: Kıyı / ada | N2: 16 | O2: Düşük | P2: 13.68 | Q2: 19.62 | R2: TR9 Doğu Karadeniz | S2: 17.63 | T2: İl düzeyi Endeksa proxy | U2: 33057 | V2: 159 | W2: 20806 | X2: 4793265 | Y2: 29.65 | Z2: 17 | AA2: Satılık stok: 3220; kiralık stok: 2790 | AB2: Adli puan İBBS-1 resmi bölge verisinden; ilçe bazında resmi suç/adli olay serisi yok. Pahalılık puanı Endeksa ham göstergelerinin min-maks ters skorudur.
A3: samsun-atakum | B3: Samsun | C3: Atakum | D3: Samsun / Atakum | E3: 74.3 | F3: 2 | G3: 60 | H3: 1.73 | I3: 1 | J3: 253437 | K3: 2.71 | L3: 20 | M3: Kıyı / ada | N3: 15 | O3: Düşük-orta | P3: 15.18 | Q3: 18.41 | R3: TR8 Batı Karadeniz | S3: 17.88 | T3: İl düzeyi Endeksa proxy | U3: 34955 | V3: 201 | W3: 20071 | X3: 4019825 | Y3: 27.64 | Z3: 15 | AA3: Satılık stok: 12073; kiralık stok: 8071 | AB3: Adli puan İBBS-1 resmi bölge verisinden; ilçe bazında resmi suç/adli olay serisi yok. Pahalılık puanı Endeksa ham göstergelerinin min-maks ters skorudur.
A4: samsun-ilkadim | B4: Samsun | C4: İlkadım | D4: Samsun / İlkadım | E4: 72.1 | F4: 3 | G4: 91 | H4: 1.34 | I4: 2 | J4: 325775 | K4: 1.42 | L4: 20 | M4: Kıyı / ada | N4: 15 | O4: Düşük-orta | P4: 13.78 | Q4: 18.41 | R4: TR8 Batı Karadeniz | S4: 17.88 | T4: İl düzeyi Endeksa proxy | U4: 34955 | V4: 201 | W4: 20071 | X4: 4019825 | Y4: 27.64 | Z4: 15 | AA4: Satılık stok: 12073; kiralık stok: 8071 | AB4: Adli puan İBBS-1 resmi bölge verisinden; ilçe bazında resmi suç/adli olay serisi yok. Pahalılık puanı Endeksa ham göstergelerinin min-maks ters skorudur.
A5: canakkale-bozcaada | B5: Çanakkale | C5: Bozcaada | D5: Çanakkale / Bozcaada | E5: 64.9 | F5: 4 | G5: 63 | H5: 1.68 | I5: 1 | J5: 3363 | K5: 2.53 | L5: 20 | M5: Kıyı / ada | N5: 8 | O5: Yüksek | P5: 20 | Q5: 10.52 | R5: TR2 Batı Marmara | S5: 16.77 | T5: İl düzeyi Endeksa proxy | U5: 51497 | V5: 284 | W5: 25597 | X5: 6076646 | Y5: 18.03 | Z5: 15 | AA5: Satılık stok: 5194; kiralık stok: 3901 | AB5: Adli puan İBBS-1 resmi bölge verisinden; ilçe bazında resmi suç/adli olay serisi yok. Pahalılık puanı Endeksa ham göstergelerinin min-maks ters skorudur.
A6: tekirdag-suleymanpasa | B6: Tekirdağ | C6: Süleymanpaşa | D6: Tekirdağ / Süleymanpaşa | E6: 63.7 | F6: 5 | G6: 93 | H6: 1.31 | I6: 2 | J6: 223068 | K6: 1.32 | L6: 20 | M6: Kıyı / ada | N6: 10 | O6: Orta-yüksek | P6: 15.76 | Q6: 10.52 | R6: TR2 Batı Marmara | S6: 18.75 | T6: İl düzeyi Endeksa proxy | U6: 30990 | V6: 208 | W6: 20800 | X6: 3687810 | Y6: 18.55 | Z6: 12 | AA6: Satılık stok: 19584; kiralık stok: 9037 | AB6: Adli puan İBBS-1 resmi bölge verisinden; ilçe bazında resmi suç/adli olay serisi yok. Pahalılık puanı Endeksa ham göstergelerinin min-maks ters skorudur.
A7: canakkale-merkez | B7: Çanakkale | C7: Merkez | D7: Çanakkale / Merkez | E7: 62.1 | F7: 6 | G7: 53 | H7: 1.85 | I7: 1 | J7: 204454 | K7: 3.08 | L7: 20 | M7: Kıyı / ada | N7: 8 | O7: Yüksek | P7: 16.12 | Q7: 10.52 | R7: TR2 Batı Marmara | S7: 16.77 | T7: İl düzeyi Endeksa proxy | U7: 51497 | V7: 284 | W7: 25597 | X7: 6076646 | Y7: 18.03 | Z7: 15 | AA7: Satılık stok: 5194; kiralık stok: 3901 | AB7: Adli puan İBBS-1 resmi bölge verisinden; ilçe bazında resmi suç/adli olay serisi yok. Pahalılık puanı Endeksa ham göstergelerinin min-maks ters skorudur.
A8: izmir-balcova | B8: İzmir | C8: Balçova | D8: İzmir / Balçova | E8: 60.6 | F8: 7 | G8: 18 | H8: 2.9 | I8: 1 | J8: 76613 | K8: 6.58 | L8: 20 | M8: Kıyı / ada | N8: 7 | O8: Yüksek | P8: 18.59 | Q8: 4.65 | R8: TR3 Ege | S8: 15.86 | T8: İlçe düzeyi Endeksa | U8: 53445 | V8: 315 | W8: 34623 | X8: 6573735 | Y8: 24.4 | Z8: 14 | AA8: İlçe stok verisi ana tabloya aktarılmadı | AB8: Adli puan İBBS-1 resmi bölge verisinden; ilçe bazında resmi suç/adli olay serisi yok. Pahalılık puanı Endeksa ham göstergelerinin min-maks ters skorudur.
A9: mersin-yenisehir | B9: Mersin | C9: Yenişehir | D9: Mersin / Yenişehir | E9: 59.8 | F9: 8 | G9: 49 | H9: 1.95 | I9: 1 | J9: 279402 | K9: 3.42 | L9: 20 | M9: Kıyı / ada | N9: 13 | O9: Orta | P9: 14.68 | Q9: 2.89 | R9: TR6 Akdeniz | S9: 17.75 | T9: İl düzeyi Endeksa proxy | U9: 34663 | V9: 204 | W9: 22644 | X9: 4540853 | Y9: 28.92 | Z9: 14 | AA9: Satılık stok: 17484; kiralık stok: 9252 | AB9: Adli puan İBBS-1 resmi bölge verisinden; ilçe bazında resmi suç/adli olay serisi yok. Pahalılık puanı Endeksa ham göstergelerinin min-maks ters skorudur.
A10: izmir-konak | B10: İzmir | C10: Konak | D10: İzmir / Konak | E10: 59.2 | F10: 9 | G10: 11 | H10: 3.46 | I10: 1 | J10: 322393 | K10: 8.44 | L10: 20 | M10: Kıyı / ada | N10: 7 | O10: Yüksek | P10: 13.85 | Q10: 4.65 | R10: TR3 Ege | S10: 17.04 | T10: İlçe düzeyi Endeksa | U10: 42628 | V10: 306 | W10: 30637 | X10: 4944848 | Y10: 21.54 | Z10: 12 | AA10: İlçe stok verisi ana tabloya aktarılmadı | AB10: Adli puan İBBS-1 resmi bölge verisinden; ilçe bazında resmi suç/adli olay serisi yok. Pahalılık puanı Endeksa ham göstergelerinin min-maks ters skorudur.
A11: kocaeli-basiskele | B11: Kocaeli | C11: Başiskele | D11: Kocaeli / Başiskele | E11: 58.6 | F11: 10 | G11: 70 | H11: 1.56 | I11: 2 | J11: 124998 | K11: 2.14 | L11: 20 | M11: Kıyı / ada | N11: 5 | O11: Çok yüksek | P11: 17.65 | Q11: 8.19 | R11: TR4 Doğu Marmara | S11: 17.36 | T11: İl düzeyi Endeksa proxy | U11: 40219 | V11: 228 | W11: 25091 | X11: 4987156 | Y11: 22.69 | Z11: 15 | AA11: Satılık stok: 18194; kiralık stok: 11024 | AB11: Adli puan İBBS-1 resmi bölge verisinden; ilçe bazında resmi suç/adli olay serisi yok. Pahalılık puanı Endeksa ham göstergelerinin min-maks ters skorudur.
A12: antalya-konyaalti | B12: Antalya | C12: Konyaaltı | D12: Antalya / Konyaaltı | E12: 58.3 | F12: 11 | G12: 27 | H12: 2.46 | I12: 1 | J12: 196079 | K12: 5.13 | L12: 20 | M12: Kıyı / ada | N12: 12 | O12: Orta | P12: 16.28 | Q12: 2.89 | R12: TR6 Akdeniz | S12: 13.64 | T12: İlçe düzeyi Endeksa | U12: 76128 | V12: 366 | W12: 36238 | X12: 10125024 | Y12: 33.42 | Z12: 17 | AA12: İlçe stok verisi ana tabloya aktarılmadı | AB12: Adli puan İBBS-1 resmi bölge verisinden; ilçe bazında resmi suç/adli olay serisi yok. Pahalılık puanı Endeksa ham göstergelerinin min-maks ters skorudur.
A13: antalya-kemer | B13: Antalya | C13: Kemer | D13: Antalya / Kemer | E13: 57.5 | F13: 12 | G13: 80 | H13: 1.5 | I13: 2 | J13: 50436 | K13: 1.94 | L13: 20 | M13: Kıyı / ada | N13: 12 | O13: Orta | P13: 19.09 | Q13: 2.89 | R13: TR6 Akdeniz | S13: 13.09 | T13: İlçe düzeyi Endeksa | U13: 81296 | V13: 340 | W13: 29555 | X13: 12275696 | Y13: 38.75 | Z13: 20 | AA13: İlçe stok verisi ana tabloya aktarılmadı | AB13: Adli puan İBBS-1 resmi bölge verisinden; ilçe bazında resmi suç/adli olay serisi yok. Pahalılık puanı Endeksa ham göstergelerinin min-maks ters skorudur.
... A47: ankara-cankaya | B47: Ankara | C47: Çankaya | D47: Ankara / Çankaya | E47: 47.8 | F47: 46 | G47: 2 | H47: 6.9 | I47: 1 | J47: 947330 | K47: 19.81 | L47: 0 | M47: İç kesim | N47: 15 | O47: Düşük-orta | P47: 1.79 | Q47: 5.69 | R47: TR5 Batı Anadolu | S47: 15.03 | T47: İlçe düzeyi Endeksa | U47: 60160 | V47: 330 | W47: 38252 | X47: 7820800 | Y47: 25.58 | Z47: 15 | AA47: İlçe stok verisi ana tabloya aktarılmadı | AB47: Adli puan İBBS-1 resmi bölge verisinden; ilçe bazında resmi suç/adli olay serisi yok. Pahalılık puanı Endeksa ham göstergelerinin min-maks ters skorudur.
A48: istanbul-adalar | B48: İstanbul | C48: Adalar | D48: İstanbul / Adalar | E48: 47.8 | F48: 47 | G48: 55 | H48: 1.82 | I48: 1 | J48: 16979 | K48: 3 | L48: 20 | M48: Kıyı / ada | N48: 6 | O48: Yüksek+ | P48: 19.74 | Q48: 0 | R48: TR1 İstanbul | S48: 8.53 | T48: İlçe düzeyi Endeksa | U48: 107115 | V48: 518 | X48: 13389375 | AA48: İlçe stok verisi ana tabloya aktarılmadı | AB48: Adli puan İBBS-1 resmi bölge verisinden; ilçe bazında resmi suç/adli olay serisi yok. Pahalılık puanı Endeksa ham göstergelerinin min-maks ters skorudur.
A49: bursa-nilufer | B49: Bursa | C49: Nilüfer | D49: Bursa / Nilüfer | E49: 47.5 | F49: 48 | G49: 8 | H49: 4.07 | I49: 1 | J49: 561730 | K49: 10.45 | L49: 5 | M49: Aynı kıyı metrosu/ili ama içte | N49: 6 | O49: Yüksek | P49: 9.23 | Q49: 8.19 | R49: TR4 Doğu Marmara | S49: 18.09 | T49: İl düzeyi Endeksa proxy | U49: 34855 | V49: 200 | W49: 22048 | X49: 4461440 | Y49: 21.71 | Z49: 14 | AA49: Satılık stok: 17511; kiralık stok: 13997 | AB49: Adli puan İBBS-1 resmi bölge verisinden; ilçe bazında resmi suç/adli olay serisi yok. Pahalılık puanı Endeksa ham göstergelerinin min-maks ters skorudur.
A50: istanbul-eyupsultan | B50: İstanbul | C50: Eyüpsultan | D50: İstanbul / Eyüpsultan | E50: 47.4 | F50: 49 | G50: 54 | H50: 1.84 | I50: 1 | J50: 420706 | K50: 3.06 | L50: 20 | M50: Kıyı / ada | N50: 8 | O50: Yüksek | P50: 11.95 | Q50: 0 | R50: TR1 İstanbul | S50: 13.79 | T50: İlçe düzeyi Endeksa | U50: 70810 | V50: 423 | W50: 41061 | X50: 7930720 | Y50: 36.6 | Z50: 14 | AA50: İlçe stok verisi ana tabloya aktarılmadı | AB50: Adli puan İBBS-1 resmi bölge verisinden; ilçe bazında resmi suç/adli olay serisi yok. Pahalılık puanı Endeksa ham göstergelerinin min-maks ters skorudur.
A51: istanbul-uskudar | B51: İstanbul | C51: Üsküdar | D51: İstanbul / Üsküdar | E51: 47.2 | F51: 50 | G51: 16 | H51: 3.04 | I51: 1 | J51: 512981 | K51: 7.05 | L51: 20 | M51: Kıyı / ada | N51: 8 | O51: Yüksek | P51: 10.17 | Q51: 0 | R51: TR1 İstanbul | S51: 11.34 | T51: İlçe düzeyi Endeksa | U51: 105582 | V51: 434 | W51: 43860 | X51: 12353094 | Y51: 33.56 | Z51: 20 | AA51: İlçe stok verisi ana tabloya aktarılmadı | AB51: Adli puan İBBS-1 resmi bölge verisinden; ilçe bazında resmi suç/adli olay serisi yok. Pahalılık puanı Endeksa ham göstergelerinin min-maks ters skorudur.
A52: istanbul-maltepe | B52: İstanbul | C52: Maltepe | D52: İstanbul / Maltepe | E52: 47.2 | F52: 51 | G52: 20 | H52: 2.69 | I52: 1 | J52: 524921 | K52: 5.86 | L52: 20 | M52: Kıyı / ada | N52: 8 | O52: Yüksek | P52: 9.94 | Q52: 0 | R52: TR1 İstanbul | S52: 12.77 | T52: İlçe düzeyi Endeksa | U52: 87972 | V52: 451 | W52: 40601 | X52: 8797200 | Y52: 38.29 | Z52: 16 | AA52: İlçe stok verisi ana tabloya aktarılmadı | AB52: Adli puan İBBS-1 resmi bölge verisinden; ilçe bazında resmi suç/adli olay serisi yok. Pahalılık puanı Endeksa ham göstergelerinin min-maks ters skorudur.
A53: istanbul-kartal | B53: İstanbul | C53: Kartal | D53: İstanbul / Kartal | E53: 47.2 | F53: 52 | G53: 35 | H53: 2.32 | I53: 1 | J53: 475859 | K53: 4.66 | L53: 20 | M53: Kıyı / ada | N53: 8 | O53: Yüksek | P53: 10.89 | Q53: 0 | R53: TR1 İstanbul | S53: 13.05 | T53: İlçe düzeyi Endeksa | U53: 76243 | V53: 424 | W53: 42423 | X53: 8310487 | Y53: 45.16 | Z53: 15 | AA53: İlçe stok verisi ana tabloya aktarılmadı | AB53: Adli puan İBBS-1 resmi bölge verisinden; ilçe bazında resmi suç/adli olay serisi yok. Pahalılık puanı Endeksa ham göstergelerinin min-maks ters skorudur.
A54: ankara-altindag | B54: Ankara | C54: Altındağ | D54: Ankara / Altındağ | E54: 47.1 | F54: 53 | G54: 22 | H54: 2.53 | I54: 1 | J54: 414893 | K54: 5.34 | L54: 0 | M54: İç kesim | N54: 15 | O54: Düşük-orta | P54: 12.06 | Q54: 5.69 | R54: TR5 Batı Anadolu | S54: 18.45 | T54: İlçe düzeyi Endeksa | U54: 30826 | V54: 194 | X54: 4007380 | AA54: İlçe stok verisi ana tabloya aktarılmadı | AB54: Adli puan İBBS-1 resmi bölge verisinden; ilçe bazında resmi suç/adli olay serisi yok. Pahalılık puanı Endeksa ham göstergelerinin min-maks ters skorudur.
A55: kayseri-kocasinan | B55: Kayseri | C55: Kocasinan | D55: Kayseri / Kocasinan | E55: 46.9 | F55: 54 | G55: 71 | H55: 1.56 | I55: 2 | J55: 416124 | K55: 2.13 | L55: 0 | M55: İç kesim | N55: 13 | O55: Orta | P55: 12.04 | Q55: 10.32 | R55: TR7 Orta Anadolu | S55: 18.77 | T55: İl düzeyi Endeksa proxy | U55: 22384 | V55: 122 | W55: 17288 | X55: 3491904 | Y55: 30.14 | Z55: 15 | AA55: Satılık stok: 9326; kiralık stok: 4828 | AB55: Adli puan İBBS-1 resmi bölge verisinden; ilçe bazında resmi suç/adli olay serisi yok. Pahalılık puanı Endeksa ham göstergelerinin min-maks ters skorudur.
A56: istanbul-sariyer | B56: İstanbul | C56: Sarıyer | D56: İstanbul / Sarıyer | E56: 46.3 | F56: 55 | G56: 14 | H56: 3.25 | I56: 1 | J56: 342582 | K56: 7.73 | L56: 20 | M56: Kıyı / ada | N56: 8 | O56: Yüksek | P56: 13.46 | Q56: 0 | R56: TR1 İstanbul | S56: 6.33 | T56: İlçe düzeyi Endeksa | U56: 148699 | V56: 602 | W56: 74033 | X56: 22304850 | Y56: 26.67 | Z56: 21 | AA56: İlçe stok verisi ana tabloya aktarılmadı | AB56: Adli puan İBBS-1 resmi bölge verisinden; ilçe bazında resmi suç/adli olay serisi yok. Pahalılık puanı Endeksa ham göstergelerinin min-maks ters skorudur.
A57: ankara-golbasi | B57: Ankara | C57: Gölbaşı | D57: Ankara / Gölbaşı | E57: 46.3 | F57: 56 | G57: 57 | H57: 1.79 | I57: 1 | J57: 165201 | K57: 2.9 | L57: 0 | M57: İç kesim | N57: 15 | O57: Düşük-orta | P57: 16.88 | Q57: 5.69 | R57: TR5 Batı Anadolu | S57: 15.06 | T57: İlçe düzeyi Endeksa | U57: 69322 | V57: 377 | W57: 31329 | X57: 7556098 | Y57: 23.7 | Z57: 15 | AA57: İlçe stok verisi ana tabloya aktarılmadı | AB57: Adli puan İBBS-1 resmi bölge verisinden; ilçe bazında resmi suç/adli olay serisi yok. Pahalılık puanı Endeksa ham göstergelerinin min-maks ters skorudur.
A58: istanbul-avcilar | B58: İstanbul | C58: Avcılar | D58: İstanbul / Avcılar | E58: 45.9 | F58: 57 | G58: 66 | H58: 1.64 | I58: 1 | J58: 440934 | K58: 2.4 | L58: 20 | M58: Kıyı / ada | N58: 6 | O58: Yüksek+ | P58: 11.56 | Q58: 0 | R58: TR1 İstanbul | S58: 15.17 | T58: İlçe düzeyi Endeksa | U58: 49792 | V58: 318 | W58: 33115 | X58: 5775872 | Y58: 53.35 | Z58: 13 | AA58: İlçe stok verisi ana tabloya aktarılmadı | AB58: Adli puan İBBS-1 resmi bölge verisinden; ilçe bazında resmi suç/adli olay serisi yok. Pahalılık puanı Endeksa ham göstergelerinin min-maks ters skorudur.
A59: ankara-yenimahalle | B59: Ankara | C59: Yenimahalle | D59: Ankara / Yenimahalle | E59: 45.7 | F59: 58 | G59: 5 | H59: 4.48 | I59: 1 | J59: 714866 | K59: 11.8 | L59: 0 | M59: İç kesim | N59: 15 | O59: Düşük-orta | P59: 6.28 | Q59: 5.69 | R59: TR5 Batı Anadolu | S59: 16.04 | T59: İlçe düzeyi Endeksa | U59: 47726 | V59: 272 | W59: 31802 | X59: 6681640 | Y59: 29.6 | Z59: 15 | AA59: İlçe stok verisi ana tabloya aktarılmadı | AB59: Adli puan İBBS-1 resmi bölge verisinden; ilçe bazında resmi suç/adli olay serisi yok. Pahalılık puanı Endeksa ham göstergelerinin min-maks ters skorudur.
A60: istanbul-bayrampasa | B60: İstanbul | C60: Bayrampaşa | D60: İstanbul / Bayrampaşa | E60: 45.6 | F60: 59 | G60: 36 | H60: 2.27 | I60: 1 | J60: 268303 | K60: 4.47 | L60: 12 | M60: Kıyıya yakın metropol içi | N60: 8 | O60: Yüksek | P60: 14.89 | Q60: 0 | R60: TR1 İstanbul | S60: 15.34 | T60: İlçe düzeyi Endeksa | U60: 58028 | V60: 336 | W60: 31284 | X60: 6150968 | Y60: 38.59 | Z60: 14 | AA60: İlçe stok verisi ana tabloya aktarılmadı | AB60: Adli puan İBBS-1 resmi bölge verisinden; ilçe bazında resmi suç/adli olay serisi yok. Pahalılık puanı Endeksa ham göstergelerinin min-maks ters skorudur.
A61: konya-karatay | B61: Konya | C61: Karatay | D61: Konya / Karatay | E61: 45.6 | F61: 60 | G61: 82 | H61: 1.48 | I61: 2 | J61: 385432 | K61: 1.88 | L61: 0 | M61: İç kesim | N61: 16 | O61: Düşük | P61: 12.63 | Q61: 5.69 | R61: TR5 Batı Anadolu | S61: 18.53 | T61: İl düzeyi Endeksa proxy | U61: 28842 | V61: 166 | W61: 21807 | X61: 4355142 | Y61: 19.94 | Z61: 14 | AA61: Satılık stok: 11282; kiralık stok: 6855 | AB61: Adli puan İBBS-1 resmi bölge verisinden; ilçe bazında resmi suç/adli olay serisi yok. Pahalılık puanı Endeksa ham göstergelerinin min-maks ters skorudur.
A62: kayseri-melikgazi | B62: Kayseri | C62: Melikgazi | D62: Kayseri / Melikgazi | E62: 45.3 | F62: 61 | G62: 46 | H62: 1.98 | I62: 1 | J62: 589989 | K62: 3.54 | L62: 0 | M62: İç kesim | N62: 13 | O62: Orta | P62: 8.68 | Q62: 10.32 | R62: TR7 Orta Anadolu | S62: 18.77 | T62: İl düzeyi Endeksa proxy | U62: 22384 | V62: 122 | W62: 17288 | X62: 3491904 | Y62: 30.14 | Z62: 15 | AA62: Satılık stok: 9326; kiralık stok: 4828 | AB62: Adli puan İBBS-1 resmi bölge verisinden; ilçe bazında resmi suç/adli olay serisi yok. Pahalılık puanı Endeksa ham göstergelerinin min-maks ters skorudur.
A63: istanbul-zeytinburnu | B63: İstanbul | C63: Zeytinburnu | D63: İstanbul / Zeytinburnu | E63: 45.1 | F63: 62 | G63: 29 | H63: 2.38 | I63: 1 | J63: 278344 | K63: 4.86 | L63: 20 | M63: Kıyı / ada | N63: 6 | O63: Yüksek+ | P63: 14.7 | Q63: 0 | R63: TR1 İstanbul | S63: 8.51 | T63: İlçe düzeyi Endeksa | U63: 86346 | V63: 624 | W63: 63012 | X63: 8979984 | Y63: 105.13 | Z63: 12 | AA63: İlçe stok verisi ana tabloya aktarılmadı | AB63: Adli puan İBBS-1 resmi bölge verisinden; ilçe bazında resmi suç/adli olay serisi yok. Pahalılık puanı Endeksa ham göstergelerinin min-maks ters skorudur.
A64: istanbul-pendik | B64: İstanbul | C64: Pendik | D64: İstanbul / Pendik | E64: 44.8 | F64: 63 | G64: 24 | H64: 2.48 | I64: 1 | J64: 749356 | K64: 5.2 | L64: 20 | M64: Kıyı / ada | N64: 8 | O64: Yüksek | P64: 5.61 | Q64: 0 | R64: TR1 İstanbul | S64: 14.88 | T64: İlçe düzeyi Endeksa | U64: 64505 | V64: 339 | W64: 33562 | X64: 6902035 | Y64: 31.86 | Z64: 16 | AA64: İlçe stok verisi ana tabloya aktarılmadı | AB64: Adli puan İBBS-1 resmi bölge verisinden; ilçe bazında resmi suç/adli olay serisi yok. Pahalılık puanı Endeksa ham göstergelerinin min-maks ters skorudur.
A65: mugla-mentese | B65: Muğla | C65: Menteşe | D65: Muğla / Menteşe | E65: 44.8 | F65: 64 | G65: 72 | H65: 1.55 | I65: 2 | J65: 124825 | K65: 2.12 | L65: 5 | M65: Aynı kıyı metrosu/ili ama içte | N65: 10 | O65: Orta-yüksek | P65: 17.66 | Q65: 4.65 | R65: TR3 Ege | S65: 14.35 | T65: Karma: satılık ilçe, kiralık il düzeyi | U65: 60047 | V65: 353 | W65: 36698 | X65: 7746063 | Y65: 25.85 | Z65: 19 | AA65: İlçe stok verisi ana tabloya aktarılmadı | AB65: Adli puan İBBS-1 resmi bölge verisinden; ilçe bazında resmi suç/adli olay serisi yok. Pahalılık puanı Endeksa ham göstergelerinin min-maks ters skorudur.
A66: antalya-kepez | B66: Antalya | C66: Kepez | D66: Antalya / Kepez | E66: 44.8 | F66: 65 | G66: 88 | H66: 1.39 | I66: 2 | J66: 629479 | K66: 1.58 | L66: 12 | M66: Kıyıya yakın metropol içi | N66: 12 | O66: Orta | P66: 7.92 | Q66: 2.89 | R66: TR6 Akdeniz | S66: 17.29 | T66: İlçe düzeyi Endeksa | U66: 41151 | V66: 251 | X66: 4073949 | AA66: İlçe stok verisi ana tabloya aktarılmadı | AB66: Adli puan İBBS-1 resmi bölge verisinden; ilçe bazında resmi suç/adli olay serisi yok. Pahalılık puanı Endeksa ham göstergelerinin min-maks ters skorudur.
A67: istanbul-atasehir | B67: İstanbul | C67: Ataşehir | D67: İstanbul / Ataşehir | E67: 44.7 | F67: 66 | G67: 9 | H67: 3.54 | I67: 1 | J67: 414866 | K67: 8.71 | L67: 12 | M67: Kıyıya yakın metropol içi | N67: 8 | O67: Yüksek | P67: 12.06 | Q67: 0 | R67: TR1 İstanbul | S67: 12.79 | T67: İlçe düzeyi Endeksa | U67: 84698 | V67: 471 | W67: 42356 | X67: 9316780 | Y67: 36.06 | Z67: 15 | AA67: İlçe stok verisi ana tabloya aktarılmadı | AB67: Adli puan İBBS-1 resmi bölge verisinden; ilçe bazında resmi suç/adli olay serisi yok. Pahalılık puanı Endeksa ham göstergelerinin min-maks ters skorudur.
A68: istanbul-beykoz | B68: İstanbul | C68: Beykoz | D68: İstanbul / Beykoz | E68: 44.6 | F68: 67 | G68: 61 | H68: 1.73 | I68: 1 | J68: 245440 | K68: 2.71 | L68: 20 | M68: Kıyı / ada | N68: 8 | O68: Yüksek | P68: 15.33 | Q68: 0 | R68: TR1 İstanbul | S68: 7.49 | T68: İlçe düzeyi Endeksa | U68: 136356 | V68: 358 | W68: 43680 | X68: 26453064 | Y68: 27.19 | Z68: 32 | AA68: İlçe stok verisi ana tabloya aktarılmadı | AB68: Adli puan İBBS-1 resmi bölge verisinden; ilçe bazında resmi suç/adli olay serisi yok. Pahalılık puanı Endeksa ham göstergelerinin min-maks ters skorudur.
A69: istanbul-gungoren | B69: İstanbul | C69: Güngören | D69: İstanbul / Güngören | E69: 44.3 | F69: 68 | G69: 50 | H69: 1.92 | I69: 1 | J69: 264831 | K69: 3.33 | L69: 12 | M69: Kıyıya yakın metropol içi | N69: 8 | O69: Yüksek | P69: 14.96 | Q69: 0 | R69: TR1 İstanbul | S69: 14.95 | T69: İlçe düzeyi Endeksa | U69: 49234 | V69: 342 | W69: 37984 | X69: 4972634 | Y69: 55.53 | Z69: 12 | AA69: İlçe stok verisi ana tabloya aktarılmadı | AB69: Adli puan İBBS-1 resmi bölge verisinden; ilçe bazında resmi suç/adli olay serisi yok. Pahalılık puanı Endeksa ham göstergelerinin min-maks ters skorudur.
A70: eskisehir-odunpazari | B70: Eskişehir | C70: Odunpazarı | D70: Eskişehir / Odunpazarı | E70: 44.1 | F70: 69 | G70: 48 | H70: 1.95 | I70: 1 | J70: 426581 | K70: 3.43 | L70: 0 | M70: İç kesim | N70: 11 | O70: Orta-yüksek | P70: 11.84 | Q70: 8.19 | R70: TR4 Doğu Marmara | S70: 18.41 | T70: İl düzeyi Endeksa proxy | U70: 32450 | V70: 199 | W70: 19109 | X70: 3731750 | Y70: 22.21 | Z70: 14 | AA70: Satılık stok: 9956; kiralık stok: 7342 | AB70: Adli puan İBBS-1 resmi bölge verisinden; ilçe bazında resmi suç/adli olay serisi yok. Pahalılık puanı Endeksa ham göstergelerinin min-maks ters skorudur.
A71: izmir-gaziemir | B71: İzmir | C71: Gaziemir | D71: İzmir / Gaziemir | E71: 44.1 | F71: 70 | G71: 43 | H71: 2.03 | I71: 1 | J71: 136930 | K71: 3.7 | L71: 5 | M71: Aynı kıyı metrosu/ili ama içte | N71: 7 | O71: Yüksek | P71: 17.42 | Q71: 4.65 | R71: TR3 Ege | S71: 15.06 | T71: İlçe düzeyi Endeksa | U71: 62270 | V71: 291 | W71: 34929 | X71: 8157370 | Y71: 21.16 | Z71: 18 | AA71: İlçe stok verisi ana tabloya aktarılmadı | AB71: Adli puan İBBS-1 resmi bölge verisinden; ilçe bazında resmi suç/adli olay serisi yok. Pahalılık puanı Endeksa ham göstergelerinin min-maks ters skorudur.
A72: izmir-buca | B72: İzmir | C72: Buca | D72: İzmir / Buca | E72: 43.6 | F72: 71 | G72: 99 | H72: 1.23 | I72: 2 | J72: 523193 | K72: 1.04 | L72: 12 | M72: Kıyıya yakın metropol içi | N72: 7 | O72: Yüksek | P72: 9.97 | Q72: 4.65 | R72: TR3 Ege | S72: 17.67 | T72: İlçe düzeyi Endeksa | U72: 43672 | V72: 275 | W72: 23656 | X72: 4410872 | Y72: 17.79 | Z72: 13 | AA72: İlçe stok verisi ana tabloya aktarılmadı | AB72: Adli puan İBBS-1 resmi bölge verisinden; ilçe bazında resmi suç/adli olay serisi yok. Pahalılık puanı Endeksa ham göstergelerinin min-maks ters skorudur.
A73: balikesir-altieylul | B73: Balıkesir | C73: Altıeylül | D73: Balıkesir / Altıeylül | E73: 43.6 | F73: 72 | G73: 96 | H73: 1.25 | I73: 2 | J73: 185351 | K73: 1.1 | L73: 0 | M73: İç kesim | N73: 7 | O73: Yüksek | P73: 16.49 | Q73: 10.52 | R73: TR2 Batı Marmara | S73: 17.19 | T73: İl düzeyi Endeksa proxy | U73: 45950 | V73: 233 | W73: 22176 | X73: 5192350 | Y73: 22.66 | Z73: 16 | AA73: Satılık stok: 20728; kiralık stok: 8804 | AB73: Adli puan İBBS-1 resmi bölge verisinden; ilçe bazında resmi suç/adli olay serisi yok. Pahalılık puanı Endeksa ham göstergelerinin min-maks ters skorudur.
...

Sheet metric_config
A1: metric_key | B1: ui_label | C1: weight_prompt | D1: score_column | E1: score_range | F1: high_score_means | G1: frontend_helper_text | H1: default_weight
A2: socialCulture | B2: Sosyal ve kültürel imkanlar | C2: Sosyal imkanlar ve kültürel düzey senin için ne kadar önemli? | D2: social_culture_score_20 | E2: 0-20 | F2: Daha gelişmiş sosyal/kültürel yapı | G2: SEGE temelli sosyal/kültürel skor. 20 iyi, 0 zayıf. | H2: 3
A3: seaAccess | B3: Denize yakınlık | C3: Denize yakınlık senin için ne kadar önemli? | D3: sea_access_score_20 | E3: 0-20 | F3: Denize/kıyıya daha yakın olma | G3: Kıyı/ada ilçeler yüksek; iç ilçeler daha düşük puanlı. | H3: 3
A4: earthquakeSafety | B4: Deprem güvenliği | C4: Deprem riskinin düşük olması senin için ne kadar önemli? | D4: earthquake_safety_score_20 | E4: 0-20 | F4: Daha düşük deprem tehlikesi | G4: Deprem risk bandı ters puanlandı. 20 daha güvenli. | H4: 3
A5: lowCrowding | B5: Kalabalık olmaması | C5: Daha sakin ve az kalabalık bir ilçe senin için ne kadar önemli? | D5: low_crowding_score_20 | E5: 0-20 | F5: Daha düşük nüfus baskısı | G5: Nüfus baskısı ters puanlandı. 20 daha sakin/az kalabalık. | H5: 3
A6: lowJudicialIntensity | B6: Adli olay yoğunluğunun düşük olması | C6: Adli olay yoğunluğunun düşük olması senin için ne kadar önemli? | D6: judicial_low_event_score_20 | E6: 0-20 | F6: Bölgesel adli olay yoğunluğunun daha düşük olması | G6: Adalet Bakanlığı İBBS-1 bölge verisi proxy’si. İlçe bazlı kesin suç oranı değildir. | H6: 3
A7: affordability | B7: Pahalılığın düşük olması | C7: Kira/satılık konut pahalılığının düşük olması senin için ne kadar önemli? | D7: affordability_score_20 | E7: 0-20 | F7: Daha ucuz/erişilebilir konut piyasası | G7: Endeksa konut göstergeleri ters puanlandı. En pahalı yerler düşük puan aldı. | H7: 3

Sheet readme
A1: Amaç | B1: Bu dosya Cursor/React entegrasyonu için sadeleştirilmiş uygulama veri setidir.
A2: Ana veri sayfası | B2: districts_app
A3: Metrik ayarları | B3: metric_config
A4: Skor mantığı | B4: Kullanıcı her metrik için 1-5 önem puanı verir. İlçe skorları zaten 0-20 aralığında ve yüksek değer iyi anlama gelir.
A5: Formül | B5: weighted_score_100 = ((Σ metric_score_20 × user_weight) / Σ user_weight) × 5
A6: Sonuç | B6: Tüm ilçeler weighted_score_100 değerine göre büyükten küçüğe sıralanır ve ilk 5 ideal ilçe gösterilir.
A7: Kritik not | B7: judicial_low_event_score_20 ilçe suçu değildir; Adalet Bakanlığı İBBS-1 resmi bölge verisinden üretilmiş proxy puandır.
A8: Kritik not | B8: affordability_score_20 yüksekse daha ucuz/erişilebilir, düşükse daha pahalıdır.
A9: Tasarım notu | B9: Uygulamada metrik kartları, premium hissi, yumuşak animasyonlar, mobil uyum ve sonuç kartlarında açıklanabilir skor kırılımı hedeflenir.

Sheet score_playground
A1: metric_key | B1: ui_label | C1: weight_1_to_5 | D1: score_column | F1: district_id | G1: full_name | H1: weighted_score_100
A2: socialCulture | B2: Sosyal ve kültürel imkanlar | C2: 3 | D2: social_culture_score_20 | F2: =districts_app!A2 -> trabzon-ortahisar | G2: =districts_app!D2 -> Trabzon / Ortahisar | H2: =((districts_app!K2*$C$2)+(districts_app!L2*$C$3)+(districts_app!N2*$C$4)+(districts_app!P2*$C$5)+(districts_app!Q2*$C$6)+(districts_app!S2*$C$7))/SUM($C$2:$C$7)*5 -> 74.908333
A3: seaAccess | B3: Denize yakınlık | C3: 3 | D3: sea_access_score_20 | F3: =districts_app!A3 -> samsun-atakum | G3: =districts_app!D3 -> Samsun / Atakum | H3: =((districts_app!K3*$C$2)+(districts_app!L3*$C$3)+(districts_app!N3*$C$4)+(districts_app!P3*$C$5)+(districts_app!Q3*$C$6)+(districts_app!S3*$C$7))/SUM($C$2:$C$7)*5 -> 74.316667
A4: earthquakeSafety | B4: Deprem güvenliği | C4: 3 | D4: earthquake_safety_score_20 | F4: =districts_app!A4 -> samsun-ilkadim | G4: =districts_app!D4 -> Samsun / İlkadım | H4: =((districts_app!K4*$C$2)+(districts_app!L4*$C$3)+(districts_app!N4*$C$4)+(districts_app!P4*$C$5)+(districts_app!Q4*$C$6)+(districts_app!S4*$C$7))/SUM($C$2:$C$7)*5 -> 72.075
A5: lowCrowding | B5: Kalabalık olmaması | C5: 3 | D5: low_crowding_score_20 | F5: =districts_app!A5 -> canakkale-bozcaada | G5: =districts_app!D5 -> Çanakkale / Bozcaada | H5: =((districts_app!K5*$C$2)+(districts_app!L5*$C$3)+(districts_app!N5*$C$4)+(districts_app!P5*$C$5)+(districts_app!Q5*$C$6)+(districts_app!S5*$C$7))/SUM($C$2:$C$7)*5 -> 64.85
A6: lowJudicialIntensity | B6: Adli olay yoğunluğunun düşük olması | C6: 3 | D6: judicial_low_event_score_20 | F6: =districts_app!A6 -> tekirdag-suleymanpasa | G6: =districts_app!D6 -> Tekirdağ / Süleymanpaşa | H6: =((districts_app!K6*$C$2)+(districts_app!L6*$C$3)+(districts_app!N6*$C$4)+(districts_app!P6*$C$5)+(districts_app!Q6*$C$6)+(districts_app!S6*$C$7))/SUM($C$2:$C$7)*5 -> 63.625
A7: affordability | B7: Pahalılığın düşük olması | C7: 3 | D7: affordability_score_20 | F7: =districts_app!A7 -> canakkale-merkez | G7: =districts_app!D7 -> Çanakkale / Merkez | H7: =((districts_app!K7*$C$2)+(districts_app!L7*$C$3)+(districts_app!N7*$C$4)+(districts_app!P7*$C$5)+(districts_app!Q7*$C$6)+(districts_app!S7*$C$7))/SUM($C$2:$C$7)*5 -> 62.075
F8: =districts_app!A8 -> izmir-balcova | G8: =districts_app!D8 -> İzmir / Balçova | H8: =((districts_app!K8*$C$2)+(districts_app!L8*$C$3)+(districts_app!N8*$C$4)+(districts_app!P8*$C$5)+(districts_app!Q8*$C$6)+(districts_app!S8*$C$7))/SUM($C$2:$C$7)*5 -> 60.566667
F9: =districts_app!A9 -> mersin-yenisehir | G9: =districts_app!D9 -> Mersin / Yenişehir | H9: =((districts_app!K9*$C$2)+(districts_app!L9*$C$3)+(districts_app!N9*$C$4)+(districts_app!P9*$C$5)+(districts_app!Q9*$C$6)+(districts_app!S9*$C$7))/SUM($C$2:$C$7)*5 -> 59.783333
F10: =districts_app!A10 -> izmir-konak | G10: =districts_app!D10 -> İzmir / Konak | H10: =((districts_app!K10*$C$2)+(districts_app!L10*$C$3)+(districts_app!N10*$C$4)+(districts_app!P10*$C$5)+(districts_app!Q10*$C$6)+(districts_app!S10*$C$7))/SUM($C$2:$C$7)*5 -> 59.15
F11: =districts_app!A11 -> kocaeli-basiskele | G11: =districts_app!D11 -> Kocaeli / Başiskele | H11: =((districts_app!K11*$C$2)+(districts_app!L11*$C$3)+(districts_app!N11*$C$4)+(districts_app!P11*$C$5)+(districts_app!Q11*$C$6)+(districts_app!S11*$C$7))/SUM($C$2:$C$7)*5 -> 58.616667
F12: =districts_app!A12 -> antalya-konyaalti | G12: =districts_app!D12 -> Antalya / Konyaaltı | H12: =((districts_app!K12*$C$2)+(districts_app!L12*$C$3)+(districts_app!N12*$C$4)+(districts_app!P12*$C$5)+(districts_app!Q12*$C$6)+(districts_app!S12*$C$7))/SUM($C$2:$C$7)*5 -> 58.283333
F13: =districts_app!A13 -> antalya-kemer | G13: =districts_app!D13 -> Antalya / Kemer | H13: =((districts_app!K13*$C$2)+(districts_app!L13*$C$3)+(districts_app!N13*$C$4)+(districts_app!P13*$C$5)+(districts_app!Q13*$C$6)+(districts_app!S13*$C$7))/SUM($C$2:$C$7)*5 -> 57.508333
F14: =districts_app!A14 -> istanbul-fatih | G14: =districts_app!D14 -> İstanbul / Fatih | H14: =((districts_app!K14*$C$2)+(districts_app!L14*$C$3)+(districts_app!N14*$C$4)+(districts_app!P14*$C$5)+(districts_app!Q14*$C$6)+(districts_app!S14*$C$7))/SUM($C$2:$C$7)*5 -> 57.091667
F15: =districts_app!A15 -> antalya-manavgat | G15: =districts_app!D15 -> Antalya / Manavgat | H15: =((districts_app!K15*$C$2)+(districts_app!L15*$C$3)+(districts_app!N15*$C$4)+(districts_app!P15*$C$5)+(districts_app!Q15*$C$6)+(districts_app!S15*$C$7))/SUM($C$2:$C$7)*5 -> 57.058333
F16: =districts_app!A16 -> aydin-kusadasi | G16: =districts_app!D16 -> Aydın / Kuşadası | H16: =((districts_app!K16*$C$2)+(districts_app!L16*$C$3)+(districts_app!N16*$C$4)+(districts_app!P16*$C$5)+(districts_app!Q16*$C$6)+(districts_app!S16*$C$7))/SUM($C$2:$C$7)*5 -> 56.916667
F17: =districts_app!A17 -> antalya-muratpasa | G17: =districts_app!D17 -> Antalya / Muratpaşa | H17: =((districts_app!K17*$C$2)+(districts_app!L17*$C$3)+(districts_app!N17*$C$4)+(districts_app!P17*$C$5)+(districts_app!Q17*$C$6)+(districts_app!S17*$C$7))/SUM($C$2:$C$7)*5 -> 56.85
F18: =districts_app!A18 -> mugla-marmaris | G18: =districts_app!D18 -> Muğla / Marmaris | H18: =((districts_app!K18*$C$2)+(districts_app!L18*$C$3)+(districts_app!N18*$C$4)+(districts_app!P18*$C$5)+(districts_app!Q18*$C$6)+(districts_app!S18*$C$7))/SUM($C$2:$C$7)*5 -> 56.516667
F19: =districts_app!A19 -> izmir-cigli | G19: =districts_app!D19 -> İzmir / Çiğli | H19: =((districts_app!K19*$C$2)+(districts_app!L19*$C$3)+(districts_app!N19*$C$4)+(districts_app!P19*$C$5)+(districts_app!Q19*$C$6)+(districts_app!S19*$C$7))/SUM($C$2:$C$7)*5 -> 56.433333
... F101: =districts_app!A101 -> istanbul-esenyurt | G101: =districts_app!D101 -> İstanbul / Esenyurt | H101: =((districts_app!K101*$C$2)+(districts_app!L101*$C$3)+(districts_app!N101*$C$4)+(districts_app!P101*$C$5)+(districts_app!Q101*$C$6)+(districts_app!S101*$C$7))/SUM($C$2:$C$7)*5 -> 31.133333
